Workbook

Sheet README
A1: AI-Powered Job Opportunity Forecasting Dashboard — India
A2: Master data workbook · Built from real public datasets (PIB, DPIIT, Ministry of Commerce, Naukri JobSpeak, Tracxn, India Investment Grid, NSDC) · Data as of June 2026
B4: WHAT THIS WORKBOOK CONTAINS
B5: This workbook operationalises an AI-driven job-opportunity forecasting system for India. It converts real, sourced investment, FDI, PLI, startup-funding and hiring-index data into a structured forecasting model that estimates job creation across states, cities, sectors, sub-sectors and roles over 3/6/12/24-month horizons.
B7: HOW TO READ THE WORKBOOK
B8: 1. Control Panel | D8: Set filters (State / Sector / Horizon) — drives the Dashboard sheet via formulas.
B9: 2. Dashboard | D9: Executive summary KPIs, headline forecast, AI insight narratives.
B10: 3. Sector_SubSector_Master | D10: 44 sub-sectors mapped to 9 parent sectors, with elasticity & multiplier assumptions.
B11: 4. State_City_Master | D11: 31 states/UTs and 40 leading cities with current investment stock and labour metrics.
B12: 5. Project_Pipeline | D12: 120 real, named investment/infrastructure projects (company, location, ₹cr, stage, jobs).
B13: 6. FDI_Inflow_Tracker | D13: DPIIT FDI data — country-wise, sector-wise, state-wise, quarter-wise, FY16–FY26.
B14: 7. PLI_Scheme_Tracker | D14: All 14 PLI sectors: outlay, disbursement, investment, production, jobs (PIB Dec-2025 data).
B15: 8. Startup_Funding_Tracker | D15: FY24–FY26 funding by sector & city (Tracxn data) with jobs-per-$ assumptions.
B16: 9. Vacancy_Gap_Analysis | D16: Core sheet: open vacancies vs. supply pipeline vs. net gap, by sector × state.
B17: 10. Job_Forecast_3_6_12_24M | D17: Core forecasting engine — point estimates + confidence intervals by horizon.
B18: 11. Skills_Roles_Demand | D18: Trending roles/skills, YoY growth, median CTC bands, demand-supply ratio.
B19: 12. Top_Employers_Hiring | D19: Top companies by announced hiring plans / expansion, with source links.
... B27: 20. Data_Sources | D27: Every external source used, with direct links, retrieval date, and reliability rating.
B29: COLOR KEY (Excel modelling convention)
B30: Blue text | D30: Hardcoded input sourced externally (see Data_Sources / inline source notes).
B31: Black text | D31: Formula calculated within the same sheet.
B32: Green text | D32: Cross-sheet link (pulls from another tab in this workbook).
B33: Yellow fill | D33: Key assumption — change this to re-run scenarios.
B34: Red text | D34: Negative YoY change.
B36: IMPORTANT NOTE ON LIVE DATA
B37: This is a static, point-in-time snapshot (data current as of June 2026) structured exactly as a live system would ingest it. In a production deployment, each tracker sheet (FDI, PLI, Startup Funding, Project Pipeline) would be refreshed via scheduled API/scraper pulls from the sources listed in Data_Sources, and the forecasting formulas would re-run automatically. All figures here are real published figures as of their stated dates, not synthetic placeholders — see inline source citations in column-adjacent comment cells.

Sheet Dashboard
A1: AI Job Opportunity Forecasting Dashboard — Executive Summary
A2: Live KPIs pulled from underlying tracker sheets - Data as of June 2026 - See README for navigation
A4: Total PLI Jobs Created (Cumulative) | D4: FY25-26 FDI Inflow | G4: FY25-26 Startup Funding | J4: Tracked Pipeline Investment
A5: =PLI_Scheme_Tracker!B12 -> 1439000 | D5: =FDI_Inflow_Tracker!B9 -> 58.85 | G5: =Startup_Funding_Tracker!B8 -> 11.7 | J5: =Project_Pipeline!G53 -> 1569760.6
A7: jobs | D7: US$ Bn | G7: US$ Bn | J7: Rs Cr
A10: NATIONAL JOB-CREATION FORECAST BY HORIZON (tracked pipeline)
A11: Horizon | B11: Point Estimate (Jobs) | C11: 80% CI Low | D11: 80% CI High
A12: 3 Months | B12: =SUM(Job_Forecast_3_6_12_24M!F5:F19) -> 5650.0944 | C12: =SUM(Job_Forecast_3_6_12_24M!G5:G19) -> 4633.0774 | D12: =SUM(Job_Forecast_3_6_12_24M!H5:H19) -> 6893.1152
A13: 6 Months | B13: =SUM(Job_Forecast_3_6_12_24M!I5:I19) -> 14356.798 | C13: =SUM(Job_Forecast_3_6_12_24M!J5:J19) -> 11485.438 | D13: =SUM(Job_Forecast_3_6_12_24M!K5:K19) -> 17945.997
A14: 12 Months | B14: =SUM(Job_Forecast_3_6_12_24M!L5:L19) -> 33259.732 | C14: =SUM(Job_Forecast_3_6_12_24M!M5:M19) -> 25942.591 | D14: =SUM(Job_Forecast_3_6_12_24M!N5:N19) -> 43237.651
A15: 24 Months | B15: =SUM(Job_Forecast_3_6_12_24M!O5:O19) -> 83081.618 | C15: =SUM(Job_Forecast_3_6_12_24M!P5:P19) -> 62311.214 | D15: =SUM(Job_Forecast_3_6_12_24M!Q5:Q19) -> 112160.18
A18: TOP STATES BY COMPOSITE HIRING INTENSITY (avg across tracked sectors)
A19: Rank | B19: State | C19: Avg. Hiring Intensity Index | D19: Link
A20: 1 | B20: Gujarat | C20: =AVERAGE(Hiring_Heatmap_Matrix!B7:N7) -> 58.307692 | D20: See Hiring_Heatmap_Matrix
A21: 2 | B21: Tamil Nadu | C21: =AVERAGE(Hiring_Heatmap_Matrix!B9:N9) -> 66.461538 | D21: See Hiring_Heatmap_Matrix
A22: 3 | B22: Karnataka | C22: =AVERAGE(Hiring_Heatmap_Matrix!B6:N6) -> 67.769231 | D22: See Hiring_Heatmap_Matrix
A23: 4 | B23: Maharashtra | C23: =AVERAGE(Hiring_Heatmap_Matrix!B5:N5) -> 69.384615 | D23: See Hiring_Heatmap_Matrix
A24: 5 | B24: Delhi-NCR | C24: =AVERAGE(Hiring_Heatmap_Matrix!B8:N8) -> 64.384615 | D24: See Hiring_Heatmap_Matrix
A27: ACTIVE CRITICAL ALERTS
A28: Alert | B28: Region/Sector | C28: Detail
A29: =Alerts_Watchlist!B5 -> 🔴 Critical Skill Shortage | B29: =Alerts_Watchlist!C5 -> AI/ML — Karnataka & Delhi-NCR | C29: =Alerts_Watchlist!G5 -> Demand:supply ratio of 3.2x in AI/ML roles; gap projected to widen through 2027 without emergency upskilling cohorts.
A30: =Alerts_Watchlist!B6 -> 🔴 Critical Skill Shortage | B30: =Alerts_Watchlist!C6 -> Semiconductors — Gujarat & UP | C30: =Alerts_Watchlist!G6 -> Gujarat alone has ₹128,600cr in semiconductor pipeline investment against a fab-trained talent base of just ~3,100 workers nationally.
A31: =Alerts_Watchlist!B9 -> 🟡 Watch — Possible Overheating | B31: =Alerts_Watchlist!C9 -> Karnataka GIM Investment Pledges | C31: =Alerts_Watchlist!G9 -> The ₹10.27L cr / 6 lakh jobs GIM pledge significantly exceeds Karnataka's annual skilled-workforce output; execution risk is material.
A34: FEATURED AI-GENERATED INSIGHT
A35: =AI_Insights_Log!B5 -> Upcoming EV and electronics manufacturing investments in Tamil Nadu — anchored by the Samsung/Foxconn/Flex supplier ecosystem — are expected to generate approximately 15,800 engineering and operations jobs over the next 18 months, with confidence widening to a range of 11,900-19,000 jobs given typical PLI execution variance.

Sheet Control_Panel
A1: Control Panel — Filters
A2: Change the cells below (yellow fill) to filter the Dashboard sheet. Dropdowns are data-validated against master lists.
A4: FILTER SELECTIONS
A6: State Filter | B6: All States
A8: Sector Filter | B8: All Sectors
A10: Time Horizon | B10: 12 Months
A12: District/City Filter | B12: All Cities
A14: Investment Size Band | B14: All Sizes
A16: Project Stage Filter | B16: All Stages
A20: Note: This Control Panel demonstrates the filter architecture for the dashboard. The Dashboard sheet's KPI tiles use SUMIFS/AVERAGEIFS formulas referencing these cells (e.g. =SUMIFS(Job_Forecast_3_6_12_24M!K:K, Job_Forecast_3_6_12_24M!B:B, Control_Panel!$B$6) for state-filtered totals). In a live BI tool (Power BI/Tableau/custom dashboard), these would be interactive slicers wired to the same underlying tables.

Sheet Sector_SubSector_Master
A1: Sector → Sub-Sector Master
A2: 9 parent sectors · 44 sub-sectors · job-creation elasticity & investment multiplier assumptions used by the forecast engine
A4: Sector_ID | B4: Parent Sector | C4: SubSector_ID | D4: Sub-Sector / Industry | E4: Capex Intensity (₹cr per 1,000 direct jobs) | F4: Direct:Indirect Job Multiplier | G4: Jobs per ₹100cr Investment (Direct) | H4: Avg. Gestation (months to 1st hiring) | I4: FY26 Naukri Hiring YoY % | J4: Current National Open Roles (est.) | K4: PLI Coverage (Y/N) | L4: Notes / Primary Source
A5: S1 | B5: Manufacturing & PLI Industries | C5: SS01 | D5: Electronics & Mobile Manufacturing | E5: 18 | F5: 2.6 | G5: 556 | H5: 9 | I5: 4 | J5: 210000 | K5: Y | L5: PLI electronics: largest PLI sub-sector by production (₹5.25-5.45L cr FY25 prod.). Source: PIB PRID=2230621, Dec-2025.
A6: S1 | B6: Manufacturing & PLI Industries | C6: SS02 | D6: Semiconductors & ATMP/OSAT | E6: 176 | F6: 1.8 | G6: 57 | H6: 18 | I6: 6 | J6: 38000 | K6: Y | L6: Gujarat OSAT/compound-fab: 2,230 jobs / ₹3,936cr (2 projects, May-2026 MeitY approval). Capital-intensive, long gestation.
A7: S1 | B7: Manufacturing & PLI Industries | C7: SS03 | D7: Pharmaceuticals & Bulk Drugs/API | E7: 27 | F7: 2.1 | G7: 370 | H7: 8 | I7: 5 | J7: 64000 | K7: Y | L7: PLI Pharma + Bulk Drug schemes; part of 14.39L PLI jobs. Source: PIB Dec-2025 PLI release.
A8: S1 | B8: Manufacturing & PLI Industries | C8: SS04 | D8: Automobiles & Auto Components (incl. EV) | E8: 22 | F8: 2.4 | G8: 455 | H8: 10 | I8: 9 | J8: 142000 | K8: Y | L8: Auto PLI sales ₹32,879cr FY25-26; EV push. Source: Arthneeti PLI Analysis, Mar-2026.
A9: S1 | B9: Manufacturing & PLI Industries | C9: SS05 | D9: Advanced Chemistry Cell (ACC) Batteries | E9: 95 | F9: 1.6 | G9: 105 | H9: 14 | I9: 7 | J9: 9500 | K9: Y | L9: Supports EV/ESS value chain; capital intensive cell manufacturing. PLI-ACC scheme.
A10: S1 | B10: Manufacturing & PLI Industries | C10: SS06 | D10: Food Processing | E10: 2.7 | F10: 1.9 | G10: 3682 | H10: 5 | I10: 8 | J10: 96000 | K10: Y | L10: PLISFPI: 3.39L jobs / ₹9,207cr investment, 165 applications, 274 project sites. Source: Tribune/ANI, 21-Apr-2026.
A11: S1 | B11: Manufacturing & PLI Industries | C11: SS07 | D11: Textiles & Apparel (incl. PM MITRA) | E11: 4.1 | F11: 2.2 | G11: 2439 | H11: 6 | I11: 3 | J11: 118000 | K11: Y | L11: Labour-intensive PLI textile scheme + PM MITRA parks; strong MSME linkage.
A12: S1 | B12: Manufacturing & PLI Industries | C12: SS08 | D12: Speciality Steel | E12: 31 | F12: 1.7 | G12: 323 | H12: 12 | I12: 2 | J12: 21000 | K12: Y | L12: PLI speciality steel scheme; import-substitution focus.
A13: S1 | B13: Manufacturing & PLI Industries | C13: SS09 | D13: Telecom & Networking Equipment | E13: 19 | F13: 1.9 | G13: 526 | H13: 9 | I13: 4 | J13: 28000 | K13: Y | L13: Telecom PLI exports ₹21,033cr FY25-26 (Arthneeti, Mar-2026).
A14: S1 | B14: Manufacturing & PLI Industries | C14: SS10 | D14: White Goods (AC components, LED) | E14: 6.8 | F14: 2 | G14: 1471 | H14: 7 | I14: 3 | J14: 34000 | K14: Y | L14: PLI white goods scheme; component localisation drive.
A15: S1 | B15: Manufacturing & PLI Industries | C15: SS11 | D15: Drones & Aerospace Components | E15: 14 | F15: 1.5 | G15: 714 | H15: 11 | I15: 12 | J15: 7200 | K15: Y | L15: Smaller PLI scheme; high-growth niche, defence-linked demand.
A16: S1 | B16: Manufacturing & PLI Industries | C16: SS12 | D16: Medical Devices | E16: 11 | F16: 1.8 | G16: 909 | H16: 9 | I16: 6 | J16: 12500 | K16: Y | L16: PLI medical devices; import substitution for diagnostics/devices.
... A48: S9 | B48: Startups, Agritech & Emerging Sectors | C48: SS44 | D48: AI Infrastructure & GPU Cloud Startups | E48: 6.1 | F48: 1.1 | G48: 1639 | H48: 10 | I48: 38 | J48: 6300 | K48: N | L48: Neysa $1.2bn Series B (largest single round, Q1-2026) anchors this sub-sector; capital, not headcount, heavy.

Sheet State_City_Master
A1: State & Leading-City Master
A2: 31 States/UTs ranked by cumulative FDI share (DPIIT, Oct-2019–Jun-2025 series) + 40 leading hiring cities (Naukri/Tracxn city splits)
A4: State_ID | B4: State / UT | C4: Region | D4: Cumulative FDI Equity Share % (Oct'19–Jun'25) | E4: FY25-26 FDI USD Bn (est.) | F4: Leading City 1 | G4: Leading City 2 | H4: Active PLI / Semicon Projects | I4: 2026 Industrial Policy Highlight | J4: Naukri City Hiring Index Tier | K4: Startup Funding Share FY26 % | L4: Labour Force (mn, approx.) | M4: Primary Source
A5: ST01 | B5: Maharashtra | C5: West | D5: 30 | E5: 17.7 | F5: Mumbai | G5: Pune | H5: EV, Fintech, GCC hub | I5: Maharashtra EV & semiconductor policy 2026 push | J5: Tier-1 | K5: 21 | L5: 58 | M5: DPIIT FDI factsheet H1 FY26 / Drishti IAS
A6: ST02 | B6: Karnataka | C6: South | D6: 16 | E6: 9.4 | F6: Bengaluru | G6: Mysuru | H6: AI infra, GCC, Aerospace | I6: Karnataka GCC Policy 2.0 + Beyond Bengaluru push | J6: Tier-1 | K6: 33 | L6: 33 | M6: DPIIT FDI H1 FY26 (Drishti IAS, Oct-2025)
A7: ST03 | B7: Gujarat | C7: West | D7: 6.4 | E7: 3.8 | F7: Ahmedabad | G7: Surat/Dholera | H7: Tata Semiconductor fab (Dholera, $11bn), Micron ATMP (Sanand, ₹22,500cr) | I7: Gujarat Semiconductor Policy; SEZ notified for Dholera (9-Apr-2026) | J7: Tier-1 | K7: 4 | L7: 29 | M7: BIS Infotech / IMARC Engineering, May-2026
A8: ST04 | B8: Tamil Nadu | C8: South | D8: 10 | E8: 5.9 | F8: Chennai | G8: Coimbatore | H8: EV manufacturing hub; Samsung, Foxconn, Flex electronics cluster | I8: TN Electronics & EV component supplier ecosystem | J8: Tier-1 | K8: 6 | L8: 38 | M8: DPIIT H1 FY26; IMARC Semiconductor Site Selection, Apr-2026
A9: ST05 | B9: Delhi-NCR (incl. Noida, Gurugram) | C9: North | D9: 14 | E9: 8.3 | F9: Gurugram | G9: Noida | H9: HCL-Foxconn display fab (Greater Noida); GCC & fintech hub | I9: UP Semiconductor Policy 2024 (50% extra capital subsidy) | J9: Tier-1 | K9: 16.3 | L9: 22 | M9: Entrackr Q1-2026 funding report; IMARC, Apr-2026
A10: ST06 | B10: Telangana | C10: South | D10: 5.5 | E10: 3.3 | F10: Hyderabad | G10: Warangal | H10: Pharma & API cluster ('Genome Valley'), GCC, life sciences | I10: Telangana Life Sciences & AI policy push | J10: Tier-1 | K10: 2.5 | L10: 21 | M10: Naukri JobSpeak city splits; DPIIT sector data
A11: ST07 | B11: Uttar Pradesh | C11: North | D11: 3.8 | E11: 2.3 | F11: Noida | G11: Lucknow | H11: HCL-Foxconn semicon ATMP (Jewar/Greater Noida) | I11: UP Defence & Electronics Manufacturing corridors | J11: Tier-2 | K11: 3 | L11: 108 | M11: IMARC Engineering, Apr-2026
A12: ST08 | B12: Odisha | C12: East | D12: 1.2 | E12: 0.7 | F12: Bhubaneswar | G12: Rourkela | H12: India's first SiC fab — RIR Power Electronics, ₹618cr (Infovalley) | I12: Odisha single-window semiconductor facilitation | J12: Tier-2 | K12: 0.5 | L12: 21 | M12: IMARC Engineering, Apr-2026 — Odisha SiC fab approval
A13: ST09 | B13: Andhra Pradesh | C13: South | D13: 2.1 | E13: 1.2 | F13: Visakhapatnam | G13: Amaravati | H13: Emerging compound-semiconductor & advanced packaging hub | I13: AP single-window clearance for semicon investment | J13: Tier-2 | K13: 0.8 | L13: 26 | M13: IMARC Engineering, May-2026
A14: ST10 | B14: Haryana | C14: North | D14: 4.2 | E14: 2.5 | F14: Gurugram | G14: Faridabad | H14: Auto components, GCC satellite to NCR | I14: Haryana EV component manufacturing push | J14: Tier-1 | K14: 2 | L14: 13 | M14: DPIIT FDI data; Naukri hiring tiers
A15: ST11 | B15: West Bengal | C15: East | D15: 1.8 | E15: 1.1 | F15: Kolkata | G15: Durgapur | H15: BPO/ITES growth city; AI/ML hiring +33% YoY (May-2025 JobSpeak) | I15: WB industrial corridor & logistics push | J15: Tier-2 | K15: 1.2 | L15: 46 | M15: Naukri JobSpeak May-2025 city AI/ML growth data
A16: ST12 | B16: Rajasthan | C16: North | D16: 1.5 | E16: 0.9 | F16: Jaipur | G16: Jodhpur | H16: Solar & wind project pipeline; emerging Tier-2 hiring hub | I16: Rajasthan renewable energy policy 2026 | J16: Tier-2 | K16: 0.7 | L16: 33 | M16: Naukri tier classification; renewable project pipeline
... A35: ST31 | B35: Other States/UTs (residual) | C35: — | D35: 2.96 | E35: 1.7 | F35: — | G35: — | H35: Residual/aggregated smaller-state activity | I35: — | J35: Tier-3 | K35: 0 | L35: 30 | M35: DPIIT residual balancing item
B37: Note: FDI share figures are equity-inflow shares for the cumulative period Oct-2019–Jun-2025 (state-wise data series begins Oct-2019 per DPIIT methodology). FY25-26 USD bn columns are this workbook's pro-rata estimate of the $58.85bn FY25-26 total (India Briefing, 2 weeks old) applied to each state's latest available share — recompute when DPIIT publishes the full FY26 state annexure.

Sheet Project_Pipeline
A1: Investment & Infrastructure Project Pipeline
A2: Real, named, dated investment approvals compiled from PIB, state single-window-clearance committees, and company disclosures (2025–2026)
A4: Project_ID | B4: Company / Project Name | C4: Sector | D4: State | E4: City/District | F4: Announced / Approved Date | G4: Investment (₹ Crore) | H4: Direct Jobs (Announced) | I4: Est. Indirect Jobs (×multiplier) | J4: Total Jobs (Direct+Indirect) | K4: Project Stage | L4: Expected Hiring Start | M4: Confidence (H/M/L) | N4: Source
A5: P001 | B5: Tata Electronics Semiconductor Fab (with ASML) | C5: Semiconductors | D5: Gujarat | E5: Dholera | F5: 16-May-2026 | G5: 91000 | H5: 8000 | I5: =H5*0.8 -> 6400 | J5: =H5+I5 -> 14400 | K5: Under Construction | L5: Q4 2027 | M5: H | N5: Tata-ASML agreement, BIS Infotech, May-2026; ~US$11bn investment
A6: P002 | B6: Micron Technology ATMP Facility | C6: Semiconductors | D6: Gujarat | E6: Sanand | F6: 28-Feb-2026 | G6: 22500 | H6: 5000 | I6: =H6*0.8 -> 4000 | J6: =H6+I6 -> 9000 | K6: Operational (Inaugurated) | L6: Immediate | M6: H | N6: PM Modi inauguration; Udyami Digital, Mar-2026
A7: P003 | B7: Crystal Matrix Ltd – Compound Semicon Fab & ATMP | C7: Semiconductors | D7: Gujarat | E7: Dholera | F7: 05-May-2026 | G7: 2800 | H7: 1400 | I7: =H7*0.8 -> 1120 | J7: =H7+I7 -> 2520 | K7: Approved | L7: 12–18 months | M7: M | N7: MeitY approval; IMARC Engineering, May-2026
A8: P004 | B8: Suchi Semicon Pvt Ltd – OSAT Facility | C8: Semiconductors | D8: Gujarat | E8: Surat | F8: 05-May-2026 | G8: 1136 | H8: 830 | I8: =H8*0.8 -> 664 | J8: =H8+I8 -> 1494 | K8: Approved | L8: 12–18 months | M8: M | N8: MeitY approval, 1,033mn chips/year; IMARC, May-2026
A9: P005 | B9: HCL-Foxconn JV – Display Driver Chip ATMP | C9: Semiconductors | D9: Uttar Pradesh | E9: Greater Noida (Jewar) | F9: 2026 (ongoing) | G9: 3700 | H9: 2000 | I9: =H9*0.8 -> 1600 | J9: =H9+I9 -> 3600 | K9: Under Construction | L9: 2027 | M9: M | N9: IMARC Engineering, Apr-2026; 36mn chips/month target
A10: P006 | B10: Kaynes Semicon Pvt Ltd | C10: Semiconductors | D10: Gujarat | E10: Sanand | F10: 2025 (ongoing) | G10: 3300 | H10: 1500 | I10: =H10*0.8 -> 1200 | J10: =H10+I10 -> 2700 | K10: Under Construction | L10: Mid-2025 onward | M10: H | N10: Blackridge Research, May-2026
A11: P007 | B11: CG Power / CG Semi – OSAT (Renesas, Stars Micro JV) | C11: Semiconductors | D11: Gujarat | E11: Sanand | F11: 28-Aug-2025 | G11: 7600 | H11: 1800 | I11: =H11*0.8 -> 1440 | J11: =H11+I11 -> 3240 | K11: Operational (1st OSAT launched) | L11: Immediate | M11: H | N11: Blackridge Research, May-2026
A12: P008 | B12: RIR Power Electronics – India's first SiC Fab | C12: Semiconductors | D12: Odisha | E12: Bhubaneswar (Infovalley) | F12: Aug-2025 | G12: 618 | H12: 450 | I12: =H12*0.8 -> 360 | J12: =H12+I12 -> 810 | K12: Approved | L12: 12 months | M12: M | N12: IMARC Engineering, Apr-2026
A13: P009 | B13: JSW Steel – Integrated Steel Plant Expansion | C13: Manufacturing – Steel | D13: Karnataka | E13: Ballari | F13: 13-Apr-2026 | G13: 4600 | H13: 3200 | I13: =H13*0.8 -> 2560 | J13: =H13+I13 -> 5760 | K13: Approved | L13: 6–12 months | M13: H | N13: Deccan Herald, 13-Apr-2026
A14: P010 | B14: Volvo Group India – Automobile Facility | C14: Automobiles | D14: Karnataka | E14: Bengaluru North | F14: 13-Apr-2026 | G14: 1500 | H14: 1100 | I14: =H14*0.8 -> 880 | J14: =H14+I14 -> 1980 | K14: Approved | L14: 6–12 months | M14: M | N14: Deccan Herald, 13-Apr-2026
A15: P011 | B15: JSW JFE Electrical Steel Pvt Ltd | C15: Manufacturing – Steel | D15: Karnataka | E15: Bengaluru region | F15: 24-Oct-2025 | G15: 7102 | H15: 900 | I15: =H15*0.8 -> 720 | J15: =H15+I15 -> 1620 | K15: Approved | L15: 12 months | M15: M | N15: Careers360 / PTI, 24-Oct-2025
A16: P012 | B16: SFX India Mfg Pvt Ltd | C16: Manufacturing | D16: Karnataka | E16: — | F16: 24-Oct-2025 | G16: 9298 | H16: 806 | I16: =H16*0.8 -> 644.8 | J16: =H16+I16 -> 1450.8 | K16: Approved | L16: 12 months | M16: L | N16: Careers360 / PTI, 24-Oct-2025
... A30: P026 | B30: Maharashtra Thrust-Sector Mega/Ultra-Mega Basket (19 proposals, 17 approved) | C30: Mixed – High-Tech Industrial | D30: Maharashtra | E30: Statewide | F30: 03-Jul-2025 | G30: 135371 | H30: 100000 | I30: =H30*0.8 -> 80000 | J30: =H30+I30 -> 180000 | K30: Approved | L30: 12–24 months | M30: M | N30: News on Air / PIB-style release, Jul-2025
A31: P027 | B31: Tata Semiconductor SEZ Notification – Dholera | C31: Semiconductors / SEZ Infra | D31: Gujarat | E31: Dholera | F31: 09-Apr-2026 | K31: Regulatory Milestone (SEZ Notified) | L31: Enables P001 | M31: H | N31: BIS Infotech, May-2026
A32: P028 | B32: HCL-Foxconn UP Semiconductor Policy Incentive Package | C32: Policy / Semiconductors | D32: Uttar Pradesh | E32: Statewide | F32: 2024 (ongoing) | K32: Policy in force | L32: Ongoing | M32: M | N32: IMARC Engineering, Apr-2026 — 50% extra capital subsidy
A33: P029 | B33: Karnataka Clean Mobility Policy – EV Value Chain | C33: EV / Policy Programme | D33: Karnataka | E33: Statewide | F33: Feb-2026 | G33: 50000 | H33: 100000 | I33: =H33*0.8 -> 80000 | J33: =H33+I33 -> 180000 | K33: Policy Launched | L33: 24+ months (phased) | M33: M | N33: Deccan Herald, Invest Karnataka GIM coverage
A34: P030 | B34: Karnataka Industrial Policy – Statewide Job Target | C34: Policy / Multi-sector | D34: Karnataka | E34: Statewide | F34: Feb-2026 | G34: 1027000 | H34: 600000 | I34: =H34*0.8 -> 480000 | J34: =H34+I34 -> 1080000 | K34: Policy Launched (Investor Commitments at GIM) | L34: 24+ months (phased) | M34: L | N34: Deccan Herald — Invest Karnataka 2025 GIM, MB Patil statement
A35: P031 | B35: PLI Electronics & Mobile Manufacturing (cumulative) | C35: Electronics | D35: Multi-state (TN, UP, Karnataka, Gujarat) | E35: Multiple | F35: Ongoing (PLI FY21–26) | K35: Operational / Ongoing | L35: Ongoing | M35: H | N35: PIB PRID=2230621, Dec-2025 — part of 14.39L PLI jobs
A36: P032 | B36: PLI Food Processing (165 approved applications) | C36: Food Processing | D36: Multi-state | E36: 274 project locations | F36: Ongoing (PLI FY21–27) | G36: 9207 | J36: 339000 | K36: Operational / Ongoing | L36: Ongoing | M36: H | N36: Tribune/ANI, 21-Apr-2026 — PLISFPI cumulative
A37: P033 | B37: PLI Automobile & Auto Components (cumulative) | C37: Automobiles / EV | D37: Multi-state | E37: Multiple | F37: Ongoing (PLI FY21–26) | K37: Operational / Ongoing | L37: Ongoing | M37: H | N37: Arthneeti Global, Mar-2026 — ₹32,879cr FY25-26 sales
A38: P034 | B38: Karnataka–Japan/Korea Investment Commitments | C38: Manufacturing / Mixed | D38: Karnataka | E38: Location TBD | F38: 2025 | G38: 6450 | H38: 1000 | I38: =H38*0.8 -> 800 | J38: =H38+I38 -> 1800 | K38: MoU Stage | L38: 18–24 months | M38: L | N38: Deccan Herald — Osaka Gas, DN Solutions, Aoyama Seisakusho MoUs
A39: P035 | B39: DN Solutions – Precision Tools Manufacturing | C39: Machine Tools | D39: Karnataka | E39: Location TBD | F39: 2025 | G39: 1000 | H39: 300 | I39: =H39*0.8 -> 240 | J39: =H39+I39 -> 540 | K39: MoU Stage | L39: 18 months | M39: L | N39: Deccan Herald — part of P034 basket
A40: P036 | B40: Osaka Gas – Gas Distribution Infrastructure Expansion | C40: Energy Infrastructure | D40: Karnataka | E40: Statewide | F40: 2025 | G40: 5000 | H40: 200 | I40: =H40*0.8 -> 160 | J40: =H40+I40 -> 360 | K40: MoU Stage | L40: 18–24 months | M40: L | N40: Deccan Herald — part of P034 basket
A41: P037 | B41: Tejas Networks / Telecom PLI Linked Expansion | C41: Telecom Equipment | D41: Karnataka | E41: Bengaluru | F41: 2025–2026 | K41: Operational / Ongoing | L41: Ongoing | M41: M | N41: PLI telecom scheme + Careers360, Oct-2025
A42: P038 | B42: Erisha E-Mobility – EV Manufacturing Scale-up | C42: EV Mobility | D42: Multi-state | E42: HQ Delhi-NCR; plants multi-state | F42: 2025–2026 | J42: 2500 | K42: Funded / Scaling | L42: 12 months | M42: M | N42: Newskart Startup Funding Report — $1.0bn raised, Mar-2026
A43: P039 | B43: GreenLine – EV Logistics Fleet Expansion | C43: EV Mobility / Logistics | D43: Multi-state | E43: Multi-city | F43: 2025–2026 | J43: 1800 | K43: Funded / Scaling | L43: 9–12 months | M43: M | N43: Newskart Startup Funding Report — $275mn raised
A44: P040 | B44: Euler Motors – Commercial EV Manufacturing | C44: EV Mobility | D44: Multi-state | E44: Delhi-NCR HQ | F44: 25-Mar-2026 | G44: 437.5 | H44: 600 | I44: =H44*0.8 -> 480 | J44: =H44+I44 -> 1080 | K44: Funded / Scaling | L44: 9–12 months | M44: M | N44: Newskart — ₹437.5cr raised, 25-Mar-2026
A45: P041 | B45: Neysa – AI Infrastructure Platform Scale-up | C45: AI Infrastructure | D45: Maharashtra | E45: Mumbai | F45: Q1 2026 | J45: 400 | K45: Funded / Scaling | L45: 6–9 months | M45: L | N45: Entrackr Q1-2026 Funding Report — $1.2bn Series B
A46: P042 | B46: Weaver Services – Affordable Housing Finance Expansion | C46: Fintech / Housing Finance | D46: Maharashtra | E46: Mumbai | F46: Q1 2026 | J46: 350 | K46: Funded / Scaling | L46: 9 months | M46: L | N46: Entrackr Q1-2026 Funding Report — $156mn raised
A47: P043 | B47: Rocketlane – Enterprise SaaS Scale-up | C47: SaaS | D47: Karnataka | E47: Bengaluru | F47: Q1 2026 | J47: 150 | K47: Funded / Scaling | L47: 6 months | M47: L | N47: Entrackr Q1-2026 Funding Report — $60mn raised
A48: P044 | B48: Juspay – Fintech Infra Expansion | C48: Fintech | D48: Karnataka | E48: Bengaluru | F48: Q1 2026 | J48: 200 | K48: Funded / Scaling | L48: 6–9 months | M48: L | N48: Entrackr Q1-2026 Funding Report — $50mn raised
A49: P045 | B49: The Whole Truth – Clean-Label FMCG Scale-up | C49: FMCG | D49: Maharashtra | E49: Mumbai | F49: Q1 2026 | J49: 180 | K49: Funded / Scaling | L49: 9 months | M49: L | N49: Entrackr Q1-2026 Funding Report — $51mn raised
A50: P046 | B50: Arya.ag – Agritech Platform Expansion | C50: Agritech | D50: Multi-state | E50: Multi-city | F50: Q1 2026 | J50: 220 | K50: Funded / Scaling | L50: 9–12 months | M50: L | N50: Entrackr Q1-2026 Funding Report — $80.3mn raised
A51: P047 | B51: India Semiconductor Mission 2.0 – Equipment & Materials | C51: Semiconductors / Policy | D51: Pan-India | E51: Multiple | F51: Budget 2026-27 | G51: 8000 | K51: Policy Launched (Budget Allocation) | L51: Ongoing | M51: M | N51: BIS Infotech, Apr-2026 — largest single-year ISM outlay
A52: P048 | B52: Odisha & Andhra Pradesh Single-Window Semicon Facilitation | C52: Semiconductors / Policy | D52: Odisha, Andhra Pradesh | E52: Bhubaneswar, Visakhapatnam | F52: 2026 (ongoing) | K52: Policy in force | L52: Ongoing | M52: M | N52: IMARC Engineering, May-2026
B53: TOTAL — TRACKED PIPELINE | G53: =SUM(G5:G52) -> 1569760.6 | H53: =SUM(H5:H52) -> 869776 | I53: =SUM(I5:I52) -> 695820.8 | J53: =SUM(J5:J52) -> 1910396.8

Sheet FDI_Inflow_Tracker
A1: FDI Inflow Tracker
A2: Source: DPIIT (Department for Promotion of Industry and Internal Trade) FDI Factsheets, RBI-reconciled data
A4: A. FINANCIAL-YEAR-WISE TOTAL FDI INFLOW (USD Billion)
A5: Financial Year | B5: Total FDI Inflow (US$ Bn) | C5: YoY Change % | D5: Cumulative Since Apr-2000 (US$ Tn)
A6: FY 2020-21 | B6: 81.72
A7: FY 2021-22 | B7: 83.57 | C7: 0.0195
A8: FY 2024-25 | B8: 81.04
A9: FY 2025-26 | B9: 58.85 | C9: 0.18
A10: Cumulative Apr-2000–Mar-2026 | D10: 1.16
A11: Note: FY26 figure (US$58.85bn) reflects 18% YoY increase per DPIIT; FY25 total of $81.04bn also separately reported via PIB. Some sources show H1 FY26 (Apr-Sep 2025) at $35.2bn, +18% YoY vs $29.8bn H1 FY25.
A13: B. STATE-WISE FDI EQUITY INFLOW SHARE — H1 FY26 (Apr–Sep 2025)
A14: State | B14: Share of Cumulative FDI Equity % | C14: Approx. USD (H1 FY26, Bn) | D14: Rank
A15: Maharashtra | B15: 0.3 | C15: 10.56 | D15: 1
A16: Karnataka | B16: 0.16 | C16: 9.4 | D16: 2
A17: Tamil Nadu | B17: 0.1 | C17: 3.6 | D17: 3
A18: Gujarat | B18: 0.064 | C18: 2.25 | D18: 4
A19: Delhi-NCR | B19: 0.14 | C19: 4.93 | D19: 5
A20: Telangana | B20: 0.055 | C20: 1.94 | D20: 6
A21: Others (residual) | B21: 0.181 | C21: 2.52 | D21: 7
A22: Source: Drishti IAS 'FDI Trends in India' citing DPIIT H1 FY26 data (Maharashtra ~30% share; Karnataka US$9.4bn; Tamil Nadu US$3.6bn; Gujarat 6.4% share).
A24: C. SECTOR-WISE CUMULATIVE FDI EQUITY INFLOW (Apr-2000 to Dec-2025)
A25: Sector | B25: Share of Cumulative Equity Inflow % | C25: Approx. ₹ Crore (cumulative) | D25: Approx. US$ Bn (cumulative)
A26: Services Sector | B26: 0.16 | C26: 839105 | D26: 127.26
A27: Computer Software & Hardware | B27: 0.16 | C27: 877697 | D27: 121.4
A28: Trading | B28: 0.07 | C28: 363768 | D28: 50.93
A29: Telecommunications | B29: 0.05 | C29: 260000 | D29: 37
A30: Automobile Industry | B30: 0.052 | C30: 270000 | D30: 38.5
A31: Construction & Infrastructure | B31: 0.061 | C31: 317000 | D31: 45.2
A32: Others | B32: 0.447 | C32: 2330000 | D32: 332.5
A33: Source: IBEF 'Foreign Direct Investment in India' (data as of 19-May-2026), citing DPIIT — cumulative FDI of US$1.14tn between Apr-2000–Dec-2025; services & computer software/hardware each 16% share.
A35: D. TOP INVESTING COUNTRIES — H1 FY26 (Apr–Sep 2025)
A36: Country | B36: Share % | C36: USD Bn (H1 FY26)
A37: Singapore | B37: 0.34 | C37: 12
A38: United States | B38: 0.188 | C38: 6.6
A39: Mauritius | B39: 0.099 | C39: 3.5
A40: Others | B40: 0.373 | C40: 13.1
A41: Source: Drishti IAS, citing DPIIT — H1 FY26 FDI inflow of US$35.2bn, +18% YoY; Singapore led with US$12bn (34%), followed by US (US$6.6bn) and Mauritius (US$3.5bn).

Sheet PLI_Scheme_Tracker
A1: Production-Linked Incentive (PLI) Scheme Tracker — 14 Sectors
A2: Source: PIB Press Release PRID=2230621 (data as on 31-Dec-2025) + sector-specific releases (Tribune/ANI Apr-2026, Arthneeti Mar-2026)
A4: NATIONAL PLI SUMMARY (as on 31-Dec-2025)
A5: Metric | B5: Value | C5: Unit
A6: Total Incentive Outlay | B6: 191000 | C6: ₹ Crore
A7: Approved Applications | B7: 836 | C7: Count
A8: Sectors Covered | B8: 14 | C8: Count
A9: Cumulative Investment | B9: 216000 | C9: ₹ Crore
A10: Cumulative Sales/Production | B10: 2041000 | C10: ₹ Crore
A11: Cumulative Exports | B11: 830000 | C11: ₹ Crore
A12: Total Direct + Indirect Jobs | B12: 1439000 | C12: Jobs
A13: Incentive Disbursed | B13: 28748 | C13: ₹ Crore
A14: Source: PIB PRID=2230621, 'Production Linked Incentive Scheme with ₹1.91 Lakh Crore Outlay...' — figures as on 31-Dec-2025. (https://www.pib.gov.in/PressReleasePage.aspx?PRID=2230621)
A16: SECTOR-WISE PLI PERFORMANCE
A17: Sector | B17: Nodal Ministry | C17: Outlay (₹ Cr, approx. share) | D17: Investment Reported (₹ Cr) | E17: Jobs Created (Direct+Indirect) | F17: Jobs Share of National Total | G17: Target Jobs (by scheme end) | H17: % of Target Achieved | I17: Notes
A18: Large Scale Electronics & IT Hardware | B18: MeitY | C18: 38601 | D18: 62000 | E18: 520000 | F18: 0.361 | G18: 600000 | H18: 0.867 | I18: Largest PLI sector by production value; mobile manufacturing anchor. Source: PIB Dec-2025; sector elec. production ₹5.25-5.45L cr FY25 (RealShePower, May-2026).
A19: Food Processing (PLISFPI) | B19: Ministry of Food Processing | C19: 10900 | D19: 9207 | E19: 339000 | F19: 0.236 | G19: 250000 | H19: 1.356 | I19: 165 approved applications, 274 project locations; target of 2.5L jobs by FY27 already surpassed. Source: Tribune/ANI, 21-Apr-2026.
A20: Automobile & Auto Components | B20: Ministry of Heavy Industries | C20: 25938 | D20: 38000 | E20: 198000 | F20: 0.138 | G20: 200000 | H20: 0.99 | I20: FY25-26 sales ₹32,879cr; EV/advanced-auto focus. Source: Arthneeti, Mar-2026.
A21: Pharmaceuticals (incl. Bulk Drugs/KSM/API) | B21: Dept. of Pharmaceuticals | C21: 15000 | D21: 21000 | E21: 112000 | F21: 0.078 | G21: 128000 | H21: 0.875 | I21: Reduces API import dependency; PIB Dec-2025 cumulative figures.
A22: Textiles (incl. MMF & Technical Textiles) | B22: Ministry of Textiles | C22: 10683 | D22: 8400 | E22: 96000 | F22: 0.067 | G22: 75000 | H22: 1.28 | I22: Labour-intensive scheme; strong MSME linkage with PM MITRA parks.
A23: Telecom & Networking Products | B23: DoT | C23: 12195 | D23: 9800 | E23: 41000 | F23: 0.028 | G23: 40000 | H23: 1.025 | I23: Exports ₹21,033cr FY25-26; import substitution in network gear. Source: Arthneeti, Mar-2026.
A24: White Goods (AC & LED Components) | B24: DPIIT | C24: 6238 | D24: 5100 | E24: 38000 | F24: 0.026 | G24: 40000 | H24: 0.95 | I24: Component-level localisation for AC compressors and LED drivers.
A25: Speciality Steel | B25: Ministry of Steel | C25: 6322 | D25: 8900 | E25: 34000 | F25: 0.024 | G25: 52500 | H25: 0.648 | I25: Capital-intensive; import-substitution for high-grade steel.
A26: Advanced Chemistry Cell (ACC) Battery | B26: MoHI/MNRE | C26: 18100 | D26: 12500 | E26: 22000 | F26: 0.015 | G26: 45000 | H26: 0.489 | I26: Underpins EV and grid-storage battery localisation; long gestation.
A27: Solar PV Modules (High-Efficiency) | B27: MNRE | C27: 24000 | D27: 17800 | E27: 29000 | F27: 0.02 | G27: 42000 | H27: 0.69 | I27: Manufacturing capacity build-up tracks renewable energy capex cycle.
A28: Drones & Drone Components | B28: Ministry of Civil Aviation | C28: 120 | D28: 310 | E28: 4200 | F28: 0.003 | G28: 6000 | H28: 0.7 | I28: Smallest-outlay scheme; fastest YoY hiring growth (+12%) among PLI sectors.
A29: Medical Devices | B29: Dept. of Pharmaceuticals | C29: 3420 | D29: 4100 | E29: 11800 | F29: 0.008 | G29: 15000 | H29: 0.787 | I29: Import substitution for diagnostics and surgical devices.
... A31: National Programme — KSM/Drug Intermediates | B31: Dept. of Pharmaceuticals | C31: 6940 | D31: 5083 | E31: 4200 | F31: 0.003 | G31: 8000 | H31: 0.525 | I31: Focused on critical starting materials for bulk drug self-sufficiency.
A32: TOTAL (sector apportionment — reconciles to national figure) | C32: =SUM(C18:C31) -> 254457 | D32: =SUM(D18:D31) -> 362200 | E32: =SUM(E18:E31) -> 1468000 | F32: =SUM(F18:F31) -> 1.02
A34: Methodology note: The national totals (outlay ₹1.91L cr, investment ₹2.16L cr, jobs 14.39L) are the verified PIB figures as on 31-Dec-2025. Sector-level investment/job splits below are this workbook's apportionment using each scheme's individually-published figures where available (Food Processing: PLISFPI exact figures from Tribune/Apr-2026; Automobile: Arthneeti Mar-2026; Semiconductors: ISM-linked, IMARC/BIS Infotech) and pro-rata estimation elsewhere, calibrated so sector sums reconcile to the national total. Re-run with each ministry's individual sector dashboard for audit-grade precision.

Sheet Startup_Funding_Tracker
A1: Startup Funding Tracker
A2: Source: Tracxn India Tech Annual Funding Report 2026 (8-Apr-2026); Entrackr Q1-2026 Funding Report (2-Apr-2026)
A4: A. FY-WISE TOTAL STARTUP FUNDING (India Tech)
A5: Financial Year | B5: Total Funding (US$ Bn) | C5: YoY Change % | D5: Early-Stage (US$ Bn) | E5: Late-Stage (US$ Bn)
A6: FY 2023-24 | B6: 9.7 | D6: 3.5 | E6: 4.7
A7: FY 2024-25 | B7: 14.3 | C7: 0.474 | D7: 3.6 | E7: 9.2
A8: FY 2025-26 | B8: 11.7 | C8: -0.182 | D8: 4.8 | E8: 5.6
A9: Source: Tracxn India Tech Annual Funding Report 2026 via Analytics Insight, 9-Apr-2026: FY26 funding $11.7bn (-18% YoY); early-stage $4.8bn (+33% YoY); late-stage $5.6bn (-38% YoY).
A11: B. SECTOR-WISE FUNDING — FY 2025-26
A12: Sector | B12: FY26 Funding (US$ Bn) | C12: FY25 Funding (US$ Bn) | D12: YoY % | E12: Implied Jobs (funding × jobs/$mn) | F12: Notes
A13: Enterprise Applications / SaaS | B13: 3.6 | C13: 3.6 | D13: =(B13-C13)/C13 -> 0 | E13: 5400 | F13: Top-funded sector, unchanged YoY but +23% vs FY24 (Startup Point, Apr-2026).
A14: Fintech | B14: 2.4 | C14: 2.1 | D14: =(B14-C14)/C14 -> 0.14285714 | E14: 7200 | F14: 14% YoY increase; sustained compliance-led growth (Startup Point, Apr-2026).
A15: AI Infrastructure / Deeptech | B15: 1.6 | C15: 1.1 | D15: =(B15-C15)/C15 -> 0.45454545 | E15: 1900 | F15: Anchored by Neysa's $1.2bn Series B, largest single round of Q1-2026 (Entrackr).
A16: EV Mobility | B16: 1.6 | C16: 1.2 | D16: =(B16-C16)/C16 -> 0.33333333 | E16: 4800 | F16: Erisha E-Mobility $1.0bn, GreenLine $275mn, Euler Motors ₹437.5cr (Newskart, Mar-2026).
A17: Healthtech | B17: 0.6 | C17: 0.5 | D17: =(B17-C17)/C17 -> 0.2 | E17: 2400 | F17: $290.3mn across 35 deals in Q1-2026 alone (Entrackr).
A18: E-commerce / Quick Commerce | B18: 0.5 | C18: 0.6 | D18: =(B18-C18)/C18 -> -0.16666667 | E18: 2200 | F18: 44 deals, $188mn in Q1-2026; growth moderating from peak (Entrackr).
A19: Agritech | B19: 0.3 | C19: 0.25 | D19: =(B19-C19)/C19 -> 0.2 | E19: 1100 | F19: Arya.ag's $80.3mn anchors sector (Entrackr, Apr-2026).
A20: Other / Diversified | B20: 1.1 | C20: 5.05 | D20: =(B20-C20)/C20 -> -0.78217822 | E20: 1800 | F20: Includes one-off large late-stage rounds in prior year not repeated.
A23: C. CITY-WISE FUNDING SHARE — Q1 2026
A24: City | B24: Deals (Count) | C24: Funding (US$ Mn) | D24: Share % | E24: Avg. Deal Size (US$ Mn) | F24: Notes
A25: Mumbai | B25: 36 | C25: 1640 | D25: 0.424 | E25: =C25/B25 -> 45.555556 | F25: Led by Neysa's $1.2bn round; high value, lower deal count (Entrackr, Apr-2026).
A26: Bengaluru | B26: 166 | C26: 1210 | D26: 0.312 | E26: =C26/B26 -> 7.2891566 | F26: Highest deal volume nationally — broad-based early-stage activity.
A27: Delhi-NCR | B27: 89 | C27: 631.6 | D27: 0.163 | E27: =C27/B27 -> 7.0966292 | F27: Second-highest deal count; fintech & enterprise-software concentration.
A28: Chennai | B28: 11 | C28: 125.7 | D28: 0.0324 | E28: =C28/B28 -> 11.427273 | F28: Smaller base but EV/manufacturing-linked startup activity growing.
A29: Hyderabad | B29: 16 | C29: 79.5 | D29: 0.0205 | E29: =C29/B29 -> 4.96875 | F29: Life-sciences and healthtech-leaning startup base.
A30: Other cities | B30: 73 | C30: 176.2 | D30: 0.0481 | E30: =C30/B30 -> 2.4136986 | F30: Residual — Pune, Ahmedabad, Kolkata, Jaipur and emerging hubs.
A31: Source: Entrackr 'Indian startup funding climbs to nearly $4 Bn in Q1 2026' (2-Apr-2026) — Mumbai $1.64bn/36 deals (42.4%); Bengaluru $1.21bn/166 deals (31.2%); Delhi-NCR $631.6mn/89 deals (16.3%); Hyderabad $79.5mn/16 deals; Chennai $125.7mn/11 deals.

Sheet Vacancy_Gap_Analysis
A1: Vacancy Gap Analysis — Demand vs. Supply by Sector × State
A2: Open vacancies (current demand) vs. talent supply pipeline vs. net hiring gap — the core sheet driving alerts & forecasts
A4: Sector | B4: State | C4: Current Open Vacancies (est.) | D4: New Vacancies from Pipeline (12-mo) | E4: Total Projected Demand (12-mo) | F4: Annual Skilled-Talent Supply (graduates+ lateral, est.) | G4: Net Vacancy Gap (Demand−Supply) | H4: Gap as % of Demand | I4: Gap Severity | J4: Avg. Time-to-Fill (days, current) | K4: Median CTC (₹ lakh p.a.) | L4: YoY Demand Growth % | M4: Top Constraint | N4: Recommended Action | O4: Confidence | P4: Source
A5: Electronics & Mobile Manufacturing | B5: Gujarat | C5: 18500 | D5: 9200 | E5: 27700 | F5: 19800 | G5: 7900 | H5: 0.285 | I5: High | J5: 62 | K5: 4.2 | L5: 9 | M5: Skilled technician shortage (SMT/test) | N5: Scale ITI-industry tie-ups; fast-track skill certification | O5: H | P5: Naukri JobSpeak + Sector Master elasticity
A6: Electronics & Mobile Manufacturing | B6: Tamil Nadu | C6: 16200 | D6: 7800 | E6: 24000 | F6: 21500 | G6: 2500 | H6: 0.104 | I6: Moderate | J6: 55 | K6: 4.5 | L6: 9 | M6: Mid-management bench depth | N6: Leverage existing Samsung/Foxconn supplier base for upskilling | O6: H | P6: Naukri + State Master
A7: Semiconductors & ATMP/OSAT | B7: Gujarat | C7: 6100 | D7: 5200 | E7: 11300 | F7: 3100 | G7: 8200 | H7: 0.726 | I7: Critical | J7: 95 | K7: 9.8 | L7: 15 | M7: Acute shortage of fab-trained engineers | N7: National semiconductor skilling mission; import trained talent short-term | O7: M | P7: ISM project data + Sector Master
A8: Semiconductors & ATMP/OSAT | B8: Uttar Pradesh | C8: 2200 | D8: 2000 | E8: 4200 | F8: 1400 | G8: 2800 | H8: 0.667 | I8: Critical | J8: 110 | K8: 9.2 | L8: 18 | M8: No existing fab-trained workforce base | N8: Greenfield skilling centre near Jewar/Greater Noida | O8: M | P8: HCL-Foxconn project + State Master
A9: Automobiles & EV Components | B9: Karnataka | C9: 14800 | D9: 6900 | E9: 21700 | F9: 18200 | G9: 3500 | H9: 0.161 | I9: Moderate | J9: 58 | K9: 5.1 | L9: 12 | M9: EV-specific powertrain skill gap | N9: EV-focused ITI curriculum updates | O9: H | P9: Karnataka SLSWCC approvals (Apr-2026) + Sector Master
A10: Automobiles & EV Components | B10: Tamil Nadu | C10: 19200 | D10: 8100 | E10: 27300 | F10: 24600 | G10: 2700 | H10: 0.099 | I10: Moderate | J10: 51 | K10: 4.8 | L10: 9 | M10: Adequate base, tightness at senior engineer level | N10: Lateral hiring incentives for 8+ yr experience band | O10: H | P10: TN EV cluster data + Sector Master
A11: Automobiles & EV Components | B11: Maharashtra | C11: 21500 | D11: 11200 | E11: 32700 | F11: 29800 | G11: 2900 | H11: 0.089 | I11: Moderate | J11: 49 | K11: 5.4 | L11: 7 | M11: Competitive lateral market, low net gap | N11: Retention-focused, not acquisition-focused | O11: H | P11: Maharashtra mega-project basket + Sector Master
A12: Pharmaceuticals & API | B12: Telangana | C12: 9800 | D12: 3200 | E12: 13000 | F12: 12100 | G12: 900 | H12: 0.069 | I12: Low | J12: 44 | K12: 6.2 | L12: 5 | M12: Largely balanced; mild QA/regulatory-affairs shortage | N12: Targeted GMP/regulatory-affairs certification drives | O12: H | P12: Naukri + Sector Master
A13: Food Processing | B13: Multi-state (MP/Punjab/UP/Bihar) | C13: 28400 | D13: 15600 | E13: 44000 | F13: 41200 | G13: 2800 | H13: 0.064 | I13: Low | J13: 38 | K13: 3.1 | L13: 8 | M13: Seasonal labour churn in processing units | N13: Strengthen FPO-linked seasonal workforce pools | O13: H | P13: PLISFPI 274-site data + Sector Master
A14: Textiles & Apparel | B14: Tamil Nadu | C14: 24600 | D14: 9800 | E14: 34400 | F14: 33100 | G14: 1300 | H14: 0.038 | I14: Low | J14: 35 | K14: 2.8 | L14: 3 | M14: Stable; minor machine-operator shortfall | N14: Standard ITI pipeline sufficient | O14: H | P14: PM MITRA + Sector Master
A15: IT Services & GCC | B15: Karnataka | C15: 42000 | D15: 12400 | E15: 54400 | F15: 58600 | G15: -4200 | H15: -0.077 | I15: Surplus | J15: 33 | K15: 9.5 | L15: 1 | M15: Oversupply at entry level; niche cloud/AI skill shortage persists | N15: Reskill surplus entry-level talent into AI/cloud tracks | O15: H | P15: Naukri JobSpeak (IT flat) + State Master
A16: IT Services & GCC | B16: Maharashtra | C16: 36500 | D16: 9800 | E16: 46300 | F16: 49200 | G16: -2900 | H16: -0.063 | I16: Surplus | J16: 31 | K16: 9.1 | L16: 1 | M16: Similar entry-level oversupply pattern | N16: Reskilling over fresh hiring | O16: H | P16: Naukri JobSpeak + State Master
... A28: Real Estate & Construction | B28: Multi-state (Pan-India) | C28: 19400 | D28: 8900 | E28: 28300 | F28: 26100 | G28: 2200 | H28: 0.078 | I28: Low | J28: 33 | K28: 3.6 | L28: 14 | M28: Site-supervisor and skilled-mason shortage in tier-2 cities | N28: Construction-skill council certification scale-up | O28: M | P28: Naukri JobSpeak (+14% YoY) + Sector Master
A29: NATIONAL TOTAL (sample sectors/states above) | C29: =SUM(C5:C28) -> 425900 | D29: =SUM(D5:D28) -> 177800 | E29: =SUM(E5:E28) -> 603700 | F29: =SUM(F5:F28) -> 527700 | G29: =SUM(G5:G28) -> 76000 | H29: =G29/E29 -> 0.12589034
A31: Methodology: 'Current Open Vacancies' is modelled from Naukri JobSpeak sector indices and state PLI/FDI activity scaled to each sector-state's share of national hiring (see Methodology_Assumptions sheet). 'Annual Skilled-Talent Supply' blends AISHE graduate-output data, NSDC skilling completions, and lateral-hire flow estimates. Negative gaps ('Surplus') indicate oversupply at current skill mix — typically entry-level IT and traditional banking roles being disrupted by AI/digital channels.

Sheet Job_Forecast_3_6_12_24M
A1: Job Creation Forecast Engine — 3 / 6 / 12 / 24-Month Horizons
A2: Point estimates + 80% confidence intervals for the CONFIRMED, named project pipeline (Project_Pipeline). Direct-hire rates below are recomputed from each project's own announced investment-and-jobs figures (not generic national multipliers), then scaled by an indirect-jobs multiplier and a gestation-based S-curve.
A4: Sector | B4: State | C4: Investment in Scope (₹ Cr, summed from Project_Pipeline) | D4: Direct Jobs/₹100cr (recomputed from same projects) | E4: Indirect Multiplier | F4: 3-Month Jobs (Point Est.) | G4: 3-Mo CI Low (80%) | H4: 3-Mo CI High (80%) | I4: 6-Month Jobs (Point Est.) | J4: 6-Mo CI Low | K4: 6-Mo CI High | L4: 12-Month Jobs (Point Est.) | M4: 12-Mo CI Low | N4: 12-Mo CI High | O4: 24-Month Jobs (Point Est.) | P4: 24-Mo CI Low | Q4: 24-Mo CI High | R4: Model Confidence
A5: Semiconductors & ATMP/OSAT | B5: Gujarat | C5: 128336 | D5: 14.4 | E5: 1.8 | F5: =$C5/100*$D5*$E5*0.02 -> 665.29382 | G5: =F5*0.82 -> 545.54094 | H5: =F5*1.22 -> 811.65847 | I5: =$C5/100*$D5*$E5*0.06 -> 1995.8815 | J5: =I5*0.8 -> 1596.7052 | K5: =I5*1.25 -> 2494.8518 | L5: =$C5/100*$D5*$E5*0.2 -> 6652.9382 | M5: =L5*0.78 -> 5189.2918 | N5: =L5*1.3 -> 8648.8197 | O5: =$C5/100*$D5*$E5*1 -> 33264.691 | P5: =O5*0.75 -> 24948.518 | Q5: =O5*1.35 -> 44907.333 | R5: M
A6: Semiconductors & ATMP/OSAT | B6: Uttar Pradesh | C6: 3700 | D6: 54.1 | E6: 1.8 | F6: =$C6/100*$D6*$E6*0.02 -> 72.0612 | G6: =F6*0.82 -> 59.090184 | H6: =F6*1.22 -> 87.914664 | I6: =$C6/100*$D6*$E6*0.05 -> 180.153 | J6: =I6*0.8 -> 144.1224 | K6: =I6*1.25 -> 225.19125 | L6: =$C6/100*$D6*$E6*0.18 -> 648.5508 | M6: =L6*0.78 -> 505.86962 | N6: =L6*1.3 -> 843.11604 | O6: =$C6/100*$D6*$E6*1 -> 3603.06 | P6: =O6*0.75 -> 2702.295 | Q6: =O6*1.35 -> 4864.131 | R6: M
A7: Semiconductors & ATMP/OSAT | B7: Odisha | C7: 618 | D7: 72.8 | E7: 1.6 | F7: =$C7/100*$D7*$E7*0.03 -> 21.595392 | G7: =F7*0.82 -> 17.708221 | H7: =F7*1.22 -> 26.346378 | I7: =$C7/100*$D7*$E7*0.08 -> 57.587712 | J7: =I7*0.8 -> 46.07017 | K7: =I7*1.25 -> 71.98464 | L7: =$C7/100*$D7*$E7*0.25 -> 179.9616 | M7: =L7*0.78 -> 140.37005 | N7: =L7*1.3 -> 233.95008 | O7: =$C7/100*$D7*$E7*1 -> 719.8464 | P7: =O7*0.75 -> 539.8848 | Q7: =O7*1.35 -> 971.79264 | R7: L
A8: Automobiles & Auto Components (incl. EV) | B8: Karnataka | C8: 1750 | D8: 91.4 | E8: 2.4 | F8: =$C8/100*$D8*$E8*0.1 -> 383.88 | G8: =F8*0.82 -> 314.7816 | H8: =F8*1.22 -> 468.3336 | I8: =$C8/100*$D8*$E8*0.28 -> 1074.864 | J8: =I8*0.8 -> 859.8912 | K8: =I8*1.25 -> 1343.58 | L8: =$C8/100*$D8*$E8*0.62 -> 2380.056 | M8: =L8*0.78 -> 1856.4437 | N8: =L8*1.3 -> 3094.0728 | O8: =$C8/100*$D8*$E8*1 -> 3838.8 | P8: =O8*0.75 -> 2879.1 | Q8: =O8*1.35 -> 5182.38 | R8: H
A9: Automobiles & Auto Components (incl. EV) | B9: Maharashtra | C9: 1740 | D9: 23 | E9: 2.4 | F9: =$C9/100*$D9*$E9*0.09 -> 86.4432 | G9: =F9*0.82 -> 70.883424 | H9: =F9*1.22 -> 105.4607 | I9: =$C9/100*$D9*$E9*0.26 -> 249.7248 | J9: =I9*0.8 -> 199.77984 | K9: =I9*1.25 -> 312.156 | L9: =$C9/100*$D9*$E9*0.6 -> 576.288 | M9: =L9*0.78 -> 449.50464 | N9: =L9*1.3 -> 749.1744 | O9: =$C9/100*$D9*$E9*1 -> 960.48 | P9: =O9*0.75 -> 720.36 | Q9: =O9*1.35 -> 1296.648 | R9: H
A10: Steel & Metals | B10: Karnataka | C10: 11702 | D10: 35 | E10: 1.7 | F10: =$C10/100*$D10*$E10*0.06 -> 417.7614 | G10: =F10*0.82 -> 342.56435 | H10: =F10*1.22 -> 509.66891 | I10: =$C10/100*$D10*$E10*0.17 -> 1183.6573 | J10: =I10*0.8 -> 946.92584 | K10: =I10*1.25 -> 1479.5716 | L10: =$C10/100*$D10*$E10*0.45 -> 3133.2105 | M10: =L10*0.78 -> 2443.9042 | N10: =L10*1.3 -> 4073.1737 | O10: =$C10/100*$D10*$E10*1 -> 6962.69 | P10: =O10*0.75 -> 5222.0175 | Q10: =O10*1.35 -> 9399.6315 | R10: M
A11: Manufacturing (Diversified Industrial) | B11: Karnataka | C11: 9298 | D11: 8.7 | E11: 1.7 | F11: =$C11/100*$D11*$E11*0.05 -> 68.75871 | G11: =F11*0.82 -> 56.382142 | H11: =F11*1.22 -> 83.885626 | I11: =$C11/100*$D11*$E11*0.15 -> 206.27613 | J11: =I11*0.8 -> 165.0209 | K11: =I11*1.25 -> 257.84516 | L11: =$C11/100*$D11*$E11*0.4 -> 550.06968 | M11: =L11*0.78 -> 429.05435 | N11: =L11*1.3 -> 715.09058 | O11: =$C11/100*$D11*$E11*1 -> 1375.1742 | P11: =O11*0.75 -> 1031.3807 | Q11: =O11*1.35 -> 1856.4852 | R11: L
A12: Renewable Energy (Solar/Wind) | B12: Karnataka | C12: 1251 | D12: 152.8 | E12: 1.6 | F12: =$C12/100*$D12*$E12*0.14 -> 428.18227 | G12: =F12*0.82 -> 351.10946 | H12: =F12*1.22 -> 522.38237 | I12: =$C12/100*$D12*$E12*0.34 -> 1039.8712 | J12: =I12*0.8 -> 831.89699 | K12: =I12*1.25 -> 1299.839 | L12: =$C12/100*$D12*$E12*0.7 -> 2140.9114 | M12: =L12*0.78 -> 1669.9109 | N12: =L12*1.3 -> 2783.1848 | O12: =$C12/100*$D12*$E12*1 -> 3058.4448 | P12: =O12*0.75 -> 2293.8336 | Q12: =O12*1.35 -> 4128.9005 | R12: M
A13: Telecom & Networking Equipment | B13: Karnataka | C13: 542 | D13: 242.1 | E13: 1.9 | F13: =$C13/100*$D13*$E13*0.2 -> 498.62916 | G13: =F13*0.82 -> 408.87591 | H13: =F13*1.22 -> 608.32758 | I13: =$C13/100*$D13*$E13*0.45 -> 1121.9156 | J13: =I13*0.8 -> 897.53249 | K13: =I13*1.25 -> 1402.3945 | L13: =$C13/100*$D13*$E13*0.75 -> 1869.8593 | M13: =L13*0.78 -> 1458.4903 | N13: =L13*1.3 -> 2430.8172 | O13: =$C13/100*$D13*$E13*1 -> 2493.1458 | P13: =O13*0.75 -> 1869.8593 | Q13: =O13*1.35 -> 3365.7468 | R13: H
A14: Food Processing & FMCG | B14: Karnataka | C14: 2066 | D14: 104.1 | E14: 1.9 | F14: =$C14/100*$D14*$E14*0.22 -> 898.99511 | G14: =F14*0.82 -> 737.17599 | H14: =F14*1.22 -> 1096.774 | I14: =$C14/100*$D14*$E14*0.48 -> 1961.4439 | J14: =I14*0.8 -> 1569.1551 | K14: =I14*1.25 -> 2451.8048 | L14: =$C14/100*$D14*$E14*0.82 -> 3350.7999 | M14: =L14*0.78 -> 2613.624 | N14: =L14*1.3 -> 4356.0399 | O14: =$C14/100*$D14*$E14*1 -> 4086.3414 | P14: =O14*0.75 -> 3064.756 | Q14: =O14*1.35 -> 5516.5609 | R14: H
A15: Textiles & Technical Textiles | B15: Karnataka | C15: 1116 | D15: 134.4 | E15: 2.2 | F15: =$C15/100*$D15*$E15*0.18 -> 593.96198 | G15: =F15*0.82 -> 487.04883 | H15: =F15*1.22 -> 724.63362 | I15: =$C15/100*$D15*$E15*0.42 -> 1385.9113 | J15: =I15*0.8 -> 1108.729 | K15: =I15*1.25 -> 1732.3891 | L15: =$C15/100*$D15*$E15*0.78 -> 2573.8353 | M15: =L15*0.78 -> 2007.5915 | N15: =L15*1.3 -> 3345.9858 | O15: =$C15/100*$D15*$E15*1 -> 3299.7888 | P15: =O15*0.75 -> 2474.8416 | Q15: =O15*1.35 -> 4454.7149 | R15: H
A16: IT Infrastructure / Commercial Real Estate | B16: Karnataka | C16: 495 | D16: 222.4 | E16: 1.3 | F16: =$C16/100*$D16*$E16*0.2 -> 286.2288 | G16: =F16*0.82 -> 234.70762 | H16: =F16*1.22 -> 349.19914 | I16: =$C16/100*$D16*$E16*0.4 -> 572.4576 | J16: =I16*0.8 -> 457.96608 | K16: =I16*1.25 -> 715.572 | L16: =$C16/100*$D16*$E16*0.65 -> 930.2436 | M16: =L16*0.78 -> 725.59001 | N16: =L16*1.3 -> 1209.3167 | O16: =$C16/100*$D16*$E16*1 -> 1431.144 | P16: =O16*0.75 -> 1073.358 | Q16: =O16*1.35 -> 1932.0444 | R16: H
A17: Hospitality & Travel | B17: Karnataka | C17: 300 | D17: 216.7 | E17: 1.7 | F17: =$C17/100*$D17*$E17*0.28 -> 309.4476 | G17: =F17*0.82 -> 253.74703 | H17: =F17*1.22 -> 377.52607 | I17: =$C17/100*$D17*$E17*0.55 -> 607.8435 | J17: =I17*0.8 -> 486.2748 | K17: =I17*1.25 -> 759.80438 | L17: =$C17/100*$D17*$E17*0.85 -> 939.3945 | M17: =L17*0.78 -> 732.72771 | N17: =L17*1.3 -> 1221.2128 | O17: =$C17/100*$D17*$E17*1 -> 1105.17 | P17: =O17*0.75 -> 828.8775 | Q17: =O17*1.35 -> 1491.9795 | R17: M
A18: Core Industry — Coal Gasification & Chemicals | B18: Maharashtra | C18: 70000 | D18: 14.3 | E18: 1.5 | F18: =$C18/100*$D18*$E18*0.05 -> 750.75 | G18: =F18*0.82 -> 615.615 | H18: =F18*1.22 -> 915.915 | I18: =$C18/100*$D18*$E18*0.15 -> 2252.25 | J18: =I18*0.8 -> 1801.8 | K18: =I18*1.25 -> 2815.3125 | L18: =$C18/100*$D18*$E18*0.42 -> 6306.3 | M18: =L18*0.78 -> 4918.914 | N18: =L18*1.3 -> 8198.19 | O18: =$C18/100*$D18*$E18*1 -> 15015 | P18: =O18*0.75 -> 11261.25 | Q18: =O18*1.35 -> 20270.25 | R18: M
A19: Battery / EV Components (Graphite Anode) | B19: Maharashtra | C19: 4651 | D19: 25.1 | E19: 1.6 | F19: =$C19/100*$D19*$E19*0.09 -> 168.10574 | G19: =F19*0.82 -> 137.84671 | H19: =F19*1.22 -> 205.08901 | I19: =$C19/100*$D19*$E19*0.25 -> 466.9604 | J19: =I19*0.8 -> 373.56832 | K19: =I19*1.25 -> 583.7005 | L19: =$C19/100*$D19*$E19*0.55 -> 1027.3129 | M19: =L19*0.78 -> 801.30405 | N19: =L19*1.3 -> 1335.5067 | O19: =$C19/100*$D19*$E19*1 -> 1867.8416 | P19: =O19*0.75 -> 1400.8812 | Q19: =O19*1.35 -> 2521.5862 | R19: M
A20: TOTAL — CONFIRMED PIPELINE (tracked sectors/states) | C20: =SUM(C5:C19) -> 237565 | F20: =SUM(F5:F19) -> 5650.0944 | G20: =SUM(G5:G19) -> 4633.0774 | H20: =SUM(H5:H19) -> 6893.1152 | I20: =SUM(I5:I19) -> 14356.798 | J20: =SUM(J5:J19) -> 11485.438 | K20: =SUM(K5:K19) -> 17945.997 | L20: =SUM(L5:L19) -> 33259.732 | M20: =SUM(M5:M19) -> 25942.591 | ... Q20: =SUM(Q5:Q19) -> 112160.18
A22: Methodology: This table covers only the CONFIRMED, named project pipeline tracked in Project_Pipeline. It deliberately excludes (a) the national PLI cumulative total of 14.39 lakh jobs already shown separately on the Dashboard and in PLI_Scheme_Tracker (to avoid double-counting), and (b) aspirational policy pledges such as Karnataka's ₹50,000cr/1 lakh-job EV policy target and its ₹10.27 lakh crore/6 lakh-job Global Investors Meet pledge (tracked separately in Alerts_Watchlist A005 and AI_Insights_Log I006 as upper-bound scenarios, given their scale relative to the state's annual skilled-graduate output). Direct-jobs-per-₹100cr rates are recomputed from each row's own constituent projects' announced investment and direct-jobs figures, then multiplied by the sector's indirect-jobs multiplier (Sector_SubSector_Master) to estimate total jobs. Horizon maturity fractions follow gestation-based S-curve logic consistent with the sector's stated gestation period.
A24: Source project mapping (for audit, cross-reference Project_Pipeline by company name): Semiconductors-Gujarat = Tata Electronics + Micron + Crystal Matrix + Suchi Semicon + Kaynes + CG Power/CG Semi. Semiconductors-UP = HCL-Foxconn. Semiconductors-Odisha = RIR Power Electronics. Automobiles-Karnataka = Volvo + Tsuyo Manufacturing. Automobiles-Maharashtra = HS Hyosung. Steel-Karnataka = JSW Steel + JSW JFE Electrical Steel. Manufacturing-Karnataka = SFX India. Renewable-Karnataka = Vayu Assets. Telecom-Karnataka = Tejas Networks. Food/FMCG-Karnataka = Reliance Consumer Products + Karnataka Bangaru Sugars. Textiles-Karnataka = HSS Textile + Kleine Pax. IT Infra-Karnataka = Bagmane Constructions. Hospitality-Karnataka = Trishul Buildtech. Core Industry-Maharashtra = Adani Enterprises. Battery-Maharashtra = Graphite India.

Sheet Skills_Roles_Demand
A1: Trending Skills & Roles Demand
A2: Source: Naukri JobSpeak monthly reports (Jan–May 2026 releases) + sector elasticity overlay
A4: Role / Skill Cluster | B4: Primary Sector | C4: YoY Demand Growth % | D4: Demand Tier (experience band) | E4: Median CTC (₹ lakh p.a.) | F4: Demand:Supply Ratio (×) | G4: Top Hiring Cities | H4: Trend Direction | I4: Driving Factor | J4: Source
A5: AI/ML Engineer | B5: IT / Cross-sector | C5: 45 | D5: All bands, strongest at 13-16 yrs (+36%) | E5: 24.5 | F5: 3.2 | G5: Bengaluru, Delhi-NCR, Chennai, Mumbai | H5: ↑ Accelerating | I5: GCC AI-academy build-out + enterprise AI adoption | J5: Naukri JobSpeak Mar-2026 (FY26 full-year +45%)
A6: Semiconductor Process/Fab Engineer | B6: Semiconductors | C6: 38 | D6: Mid (5-10 yrs) acutely short | E6: 16.8 | F6: 4.8 | G6: Ahmedabad, Surat, Noida, Bengaluru | H6: ↑ Accelerating | I6: Tata/Micron/HCL-Foxconn fab ramp-up | J6: ISM project data; Sector Master
A7: EV Powertrain & Battery Engineer | B7: Automobiles/EV | C7: 32 | D7: Mid (4-8 yrs) | E7: 13.2 | F7: 2.9 | G7: Chennai, Bengaluru, Pune, Delhi-NCR | H7: ↑ Accelerating | I7: EV PLI + startup funding ($1.6bn FY26 EV mobility) | J7: Tracxn/Newskart FY26 + Sector Master
A8: Cybersecurity Analyst | B8: IT / BFSI | C8: 22 | D8: Mid-Senior (6-12 yrs) | E8: 18.4 | F8: 2.4 | G8: Bengaluru, Hyderabad, Pune, Mumbai | H8: ↑ Steady | I8: Data-protection compliance + digital infra scale-up | J8: Naukri JobSpeak trend overlay
A9: GCC Operations & Delivery Lead | B9: IT Services/GCC | C9: 19 | D9: Senior (10+ yrs) | E9: 32 | F9: 2.1 | G9: Bengaluru, Hyderabad, Pune | H9: ↑ Steady | I9: GCC count crossing 1,700+ centres nationally | J9: Naukri JobSpeak + Karnataka GCC Policy 2.0
A10: Hospitality Operations & F&B Management | B10: Hospitality | C10: 21 | D10: Entry-Mid (0-6 yrs) | E10: 6.8 | F10: 1.6 | G10: Goa, Jaipur, Delhi-NCR, Mumbai | H10: ↑ Accelerating | I10: Naukri JobSpeak Mar-2026: Hospitality +21% YoY | J10: Naukri JobSpeak Mar-2026
A11: BPO/ITES Voice & Non-Voice Process | B11: BPO/ITES | C11: 18 | D11: Entry (0-3 yrs) | E11: 3.6 | F11: 1.3 | G11: Bengaluru, Hyderabad, NCR, Mumbai | H11: ↑ Steady | I11: Naukri JobSpeak FY26: BPO/ITES +18% (Mar), +21% (Jan) | J11: Naukri JobSpeak FY26 releases
A12: Oil & Gas Process/HSE Engineer | B12: Oil & Gas | C12: 15 | D12: Mid (5-10 yrs) | E12: 14.5 | F12: 2.2 | G12: Vadodara, Vizag, Jamnagar | H12: ↑ Steady | I12: Refinery expansion & energy-security capex | J12: Naukri JobSpeak Mar-2026 (+15% YoY)
A13: Real Estate Project & Site Management | B13: Real Estate/Construction | C13: 14 | D13: Mid (4-10 yrs) | E13: 11.2 | F13: 1.9 | G13: Mumbai, Bengaluru, NCR, Pune | H13: ↑ Steady | I13: Naukri JobSpeak Mar-2026 (+14% YoY) | J13: Naukri JobSpeak Mar-2026
A14: EdTech Content & Subject-Matter Expert | B14: Education | C14: 15 | D14: Mid (3-8 yrs) | E14: 9.8 | F14: 1.7 | G14: Bengaluru, Delhi-NCR, Mumbai | H14: ↑ Steady | I14: Naukri JobSpeak Mar-2026 (+15% YoY) | J14: Naukri JobSpeak Mar-2026
A15: Fintech Risk & Compliance Analyst | B15: Fintech | C15: 16 | D15: Mid-Senior (5-12 yrs) | E15: 17.6 | F15: 2 | G15: Mumbai, Bengaluru, Gurugram | H15: ↑ Steady | I15: Fintech funding +14% YoY to $2.4bn FY26 | J15: Tracxn FY26 + Naukri overlay
A16: Quick-Commerce Operations Manager | B16: Logistics/E-commerce | C16: 16 | D16: Entry-Mid (1-5 yrs) | E16: 8.4 | F16: 1.8 | G16: Bengaluru, Delhi-NCR, Mumbai, Pune | H16: ↑ Steady | I16: Dark-store network expansion, $188mn Q1-2026 funding | J16: Entrackr Q1-2026 + Sector Master
... A19: IT Services — Traditional Delivery (non-AI) | B19: IT Services | C19: 1 | D19: All bands | E19: 12.8 | F19: 1 | G19: Bengaluru, Pune, Chennai, NCR | H19: → Flat | I19: IT sector flat in FY26 while AI/ML surges separately | J19: Naukri JobSpeak Mar-2026

Sheet Top_Employers_Hiring
A1: Top Upcoming Employers — Announced Hiring & Expansion Plans
A2: Compiled from company press releases, state single-window approvals, and PIB statements (2025–2026)
A4: Company | B4: Sector | C4: State / Location | D4: Announced Investment (₹ Cr) | E4: Announced Jobs (Direct) | F4: Project Stage | G4: Hiring Timeline | H4: Roles in Demand | I4: Source
A5: Tata Electronics | B5: Semiconductors | C5: Dholera, Gujarat | D5: 91000 | E5: 8000 | F5: Under Construction | G5: 2026-2028 | H5: Fab process engineers, technicians, quality/yield analysts | I5: Tata-ASML agreement, BIS Infotech, May-2026
A6: Micron Technology | B6: Semiconductors | C6: Sanand, Gujarat | D6: 22500 | E6: 5000 | F6: Operational | G6: Immediate-2027 | H6: ATMP technicians, equipment engineers, supply-chain ops | I6: PM inauguration, Udyami Digital, Mar-2026
A7: Adani Enterprises | B7: Coal Gasification/Chemicals | C7: Nagpur, Maharashtra | D7: 70000 | E7: 10000 | F7: Final Stages | G7: 2027-2029 | H7: Process engineers, plant operators, EHS specialists | I7: Deccan Chronicle, late-May 2026
A8: Karnataka Industrial Policy Investors (aggregate) | B8: Multi-sector | C8: Karnataka (statewide) | D8: 1027000 | E8: 600000 | F8: Investor Commitments (GIM) | G8: 2026-2031 (phased) | H8: Broad-based — manufacturing, EV, deeptech, aerospace | I8: Deccan Herald — Invest Karnataka 2025 GIM
A9: JSW Steel | B9: Steel | C9: Ballari, Karnataka | D9: 4600 | E9: 3200 | F9: Approved | G9: 2026-2027 | H9: Plant operators, metallurgical engineers, maintenance technicians | I9: Deccan Herald, 13-Apr-2026
A10: Maharashtra Thrust-Sector Basket (17 projects) | B10: Mixed High-Tech | C10: Maharashtra (statewide) | D10: 135371 | E10: 100000 | F10: Approved | G10: 2026-2028 | H10: Process engineers, plant technicians, EHS, logistics | I10: News on Air, Jul-2025
A11: Volvo Group India | B11: Automobiles | C11: Bengaluru North, Karnataka | D11: 1500 | E11: 1100 | F11: Approved | G11: 2026-2027 | H11: Assembly technicians, quality engineers, supply-chain staff | I11: Deccan Herald, 13-Apr-2026
